Workbook

Sheet TruePDB
A1: Target | B1: Drug | C1: Confidence_score | D1: Affinity | E1: Affinity_score | F1: Experiment_result | G1: Affinity uM | J1: confidence averages
A2: ADRA1A | B2: Azatadine | C2: 0.91749746 | D2: -1.6217222 | E2: 0.88617766 | F2: Positive | G2: =POWER(10,D2) -> 0.02389339 | I2: ADRA1A | J2: =AVERAGE(C2:C10) -> 0.90752476
A3: ADRA1A | B3: Domperidone | C3: 0.91559613 | D3: -1.5698873 | E3: 0.88059759 | F3: Positive | G3: =POWER(10,D3) -> 0.026922335 | I3: ADRA2A | J3: =AVERAGE(C11:C17) -> 0.69699048
A4: ADRA1A | B4: Dyclonine | C4: 0.90772408 | D4: -0.11421721 | E4: 0.64782667 | F4: Positive | G4: =POWER(10,D4) -> 0.76874587 | I4: ADRA2B | J4: =AVERAGE(C18:C21) -> 0.86741818
A5: ADRA1A | B5: Ketotifen | C5: 0.91449112 | D5: -1.5621039 | E5: 0.81607008 | F5: Positive | G5: =POWER(10,D5) -> 0.027409186 | I5: ADRA2C
A6: ADRA1A | B6: Meperidine | C6: 0.92222196 | D6: -0.49306852 | E6: 0.81229532 | F6: Positive | G6: =POWER(10,D6) -> 0.32131536 | I6: ADRB1 | J6: =C31 -> 0.77468061
A7: ADRA1A | B7: Pizotifen | C7: 0.92280513 | D7: -1.9282397 | E7: 0.91925263 | F7: Positive | G7: =POWER(10,D7) -> 0.011796694 | I7: ADRB2 | J7: =AVERAGE(C32:C36) -> 0.87324623
A8: ADRA1A | B8: Rescinnamine | C8: 0.86595726 | D8: 0.7877 | E8: 0.5355916 | F8: Positive | G8: =POWER(10,D8) -> 6.1333818 | I8: AR | J8: =AVERAGE(C37:C40) -> 0.9651358
A9: ADRA1A | B9: Reserpine | C9: 0.88022155 | D9: -0.93594509 | E9: 0.71724862 | F9: Positive | G9: =POWER(10,D9) -> 0.11589239 | I9: CHRM1 | J9: =AVERAGE(C41:C44) -> 0.87898292
A10: ADRA1A | B10: Tripelennamine | C10: 0.9212082 | D10: 0.066061191 | E10: 0.70714629 | F10: Positive | G10: =POWER(10,D10) -> 1.1642901 | I10: CHRM2 | J10: =AVERAGE(C45:C49) -> 0.90578262
A11: ADRA2A | B11: Benzquinamide | C11: 0.67048514 | D11: -1.2740451 | E11: 0.84486663 | F11: Positive | G11: =POWER(10,D11) -> 0.053205299 | I11: DRD1 | J11: =AVERAGE(C50:C53) -> 0.76474884
A12: ADRA2A | B12: Buphenin | C12: 0.69625497 | D12: -0.093227297 | E12: 0.38139585 | F12: Positive | G12: =POWER(10,D12) -> 0.80681266 | I12: DRD2 | J12: =AVERAGE(C54) -> 0.9316389
A13: ADRA2A | B13: Dextromethorphan | C13: 0.70230639 | D13: 0.7225486 | E13: 0.56107074 | F13: Positive | G13: =POWER(10,D13) -> 5.2789628 | I13: DRD3 | J13: =AVERAGE(C55:C61) -> 0.92625819
A14: ADRA2A | B14: Dobutamine | C14: 0.65834105 | D14: -0.36056393 | E14: 0.43206736 | F14: Positive | G14: =POWER(10,D14) -> 0.43594938 | I14: DRD4
A15: ADRA2A | B15: Fasudil | C15: 0.74385977 | D15: 0.6898905 | E15: 0.55986118 | F15: Positive | G15: =POWER(10,D15) -> 4.8965535 | I15: GABRA1
A16: ADRA2A | B16: Levorphanol | C16: 0.69281334 | D16: 0.17820303 | E16: 0.68320173 | F16: Positive | G16: =POWER(10,D16) -> 1.5073116 | I16: HRH1
A17: ADRA2A | B17: Pizotifen | C17: 0.71487272 | D17: 0.095968589 | E17: 0.73594618 | F17: Positive | G17: =POWER(10,D17) -> 1.2472933 | I17: HRH2
A18: ADRA2B | B18: Benzphetamine | C18: 0.87103719 | D18: -0.50676209 | E18: 0.8978399 | F18: Positive | G18: =POWER(10,D18) -> 0.31134214 | I18: HRH3
A19: ADRA2B | B19: Benzquinamide | C19: 0.87746757 | D19: -0.27581015 | E19: 0.92623371 | F19: Positive | G19: =POWER(10,D19) -> 0.52989503 | I19: HTR1A
A20: ADRA2B | B20: Buphenin | C20: 0.86111444 | D20: 0.11254868 | E20: 0.84928459 | F20: Positive | G20: =POWER(10,D20) -> 1.2958319 | I20: HTR2A
A21: ADRA2B | B21: Trazodone | C21: 0.86005354 | D21: -0.7831651 | E21: 0.93801099 | F21: Positive | G21: =POWER(10,D21) -> 0.1647536 | I21: HTR2B
I22: HTR2C
I23: HTR3A
I24: KCNH2
I25: NR3C1
I26: OPRD1
I27: OPRK1
I28: OPRM1
I29: PDE4D
I30: PGR
A31: ADRB1 | B31: Tamsulosin | C31: 0.77468061 | D31: -2.4280963 | E31: 0.95794648 | F31: Positive | G31: =POWER(10,D31) -> 0.0037316741 | I31: PTGS1
A32: ADRB2 | B32: Desloratadine | C32: 0.86314601 | D32: -0.14148013 | E32: 0.98094833 | F32: Positive | G32: =POWER(10,D32) -> 0.72197119 | I32: SLC6A2
A33: ADRB2 | B33: Pimozide | C33: 0.86743301 | D33: -1.7029866 | E33: 0.95124865 | F33: Positive | G33: =POWER(10,D33) -> 0.019815882 | I33: SLC6A3
A34: ADRB2 | B34: Pizotifen | C34: 0.88174671 | D34: -1.0921493 | E34: 0.87707126 | F34: Positive | G34: =POWER(10,D34) -> 0.080881788 | I34: SLC6A4
A35: ADRB2 | B35: Prenylamine | C35: 0.87534899 | D35: -0.74084431 | E35: 0.89433193 | F35: Positive | G35: =POWER(10,D35) -> 0.18161666 | I35: TACR1
A36: ADRB2 | B36: Tamsulosin | C36: 0.87855643 | D36: -2.0233862 | E36: 0.93293542 | F36: Positive | G36: =POWER(10,D36) -> 0.0094757536
A37: AR | B37: Dihydrotachysterol | C37: 0.93575078 | D37: -0.30538064 | E37: 0.48659387 | F37: Positive | G37: =POWER(10,D37) -> 0.49501614
A38: AR | B38: Fluorometholone | C38: 0.98173696 | D38: -1.8169646 | E38: 0.93006748 | F38: Positive | G38: =POWER(10,D38) -> 0.015241769
A39: AR | B39: Medrysone | C39: 0.98093778 | D39: -1.1691692 | E39: 0.87914371 | F39: Positive | G39: =POWER(10,D39) -> 0.067737757
A40: AR | B40: Prednicarbate | C40: 0.96211767 | D40: -1.1492813 | E40: 0.74682772 | F40: Positive | G40: =POWER(10,D40) -> 0.070911837
...

Sheet TrueUni
A1: Target | B1: Drug | C1: Confidence_score | D1: Affinity | E1: Affinity_score | F1: Affinity, uM
A2: ADRA1A | B2: Azatadine | C2: 0.7631107 | D2: -0.75479603 | E2: 0.91074884 | F2: =EXP(D2) -> 0.47010649
A3: ADRA1A | B3: Domperidone | C3: 0.77878827 | D3: -1.324721 | E3: 0.86779201 | F3: =EXP(D3) -> 0.26587713
A4: ADRA1A | B4: Dyclonine | C4: 0.74377853 | D4: 0.076932229 | E4: 0.6890021 | F4: =EXP(D4) -> 1.0799689
A5: ADRA1A | B5: Ketotifen | C5: 0.7547828 | D5: -1.7113101 | E5: 0.85281724 | F5: =EXP(D5) -> 0.18062899
A6: ADRA1A | B6: Meperidine | C6: 0.7738359 | D6: -0.2551733 | E6: 0.86779165 | F6: =EXP(D6) -> 0.77478222
A7: ADRA1A | B7: Pizotifen | C7: 0.74685371 | D7: -1.6321908 | E7: 0.916821 | F7: =EXP(D7) -> 0.1955008
A8: ADRA1A | B8: Rescinnamine | C8: 0.73461568 | D8: 0.29772276 | E8: 0.78111058 | F8: =EXP(D8) -> 1.3467883
A9: ADRA1A | B9: Reserpine | C9: 0.74224615 | D9: -1.3461102 | E9: 0.80522859 | F9: =EXP(D9) -> 0.26025061
A10: ADRA1A | B10: Tripelennamine | C10: 0.75607711 | D10: 0.0058555529 | E10: 0.73450089 | F10: =EXP(D10) -> 1.0058727
A11: ADRA2A | B11: Benzquinamide | C11: 0.73124027 | D11: -0.87404162 | E11: 0.93141192 | F11: =EXP(D11) -> 0.41726172
A12: ADRA2A | B12: Buphenin | C12: 0.74259174 | D12: -0.41105884 | E12: 0.84994966 | F12: =EXP(D12) -> 0.66294792
A13: ADRA2A | B13: Dextromethorphan | C13: 0.71426052 | D13: -1.3979126 | E13: 0.84050381 | F13: =EXP(D13) -> 0.24711224
... A129: TACR1 | B129: Haloperidol | C129: 0.82469511 | D129: -0.85562956 | E129: 0.40681466 | F129: =EXP(D129) -> 0.42501553
A131: averages | C131: =AVERAGE(C2:C129) -> 0.75282224
C132: =STDEV(C2:C129) -> 0.09336042

Sheet TrueSea
A1: Drug name | B1: Drug SMILES | C1: Closest ChEMBL neighbor SMILES | D1: ECFP_4 Tc | E1: Combined Tc | F1: SEA E-value | G1: Target | H1: Closest known target | I1: BLAST E-value | J1: Confirmed activity [uM] | K1: Functional annotation | L1: LOG10
A2: Azatadine | B2: CN1CCC(CC1)=C1C2=NC=CC=C2CCC2=C1C=CC=C2 | C2: CN1CCC(=C2c(n3CCc(c24)cccc4)ccc3)CC1 | D2: 0.5 | E2: 0.5 | F2: 5e-07 | G2: ADRA1A | H2: HRH4 | I2: 4.1e-26 | J2: 8.642 | K2: Binding | L2: =-LOG10(F2) -> 6.30103
A3: Domperidone | B3: ClC1=CC2=C(C=C1)N(C1CCN(CCCN3C(=O)NC4=C3C=CC=C4)CC1)C(=O)N2 | C3: Clc1cc2c(S(=O)(=O)N(CCCCN3CCC(N4c(c5OC4=O)cccc5)CC3)C2=O)cc1 | D3: 0.43 | E3: 0.43 | F3: 2.5e-18 | G3: ADRA1A | H3: DRD1 | I3: 4.8e-50 | J3: 0.128 | K3: Binding | L3: =-LOG10(F3) -> 17.60206
A4: Dyclonine | B4: CCCCOC1=CC=C(C=C1)C(=O)CCN1CCCCC1 | C4: Fc1ccc(C(CCN2CCN(c3ncc(F)cn3)CC2)=O)cc1 | D4: 0.38 | E4: 0.38 | F4: 6e-06 | G4: ADRA1A | H4: SCN10A | I4: 2.7 | J4: 9.658 | K4: Binding | L4: =-LOG10(F4) -> 5.2218487
A5: Ketotifen | B5: CN1CCC(CC1)=C1C2=C(SC=C2)C(=O)CC2=C1C=CC=C2 | C5: CN1CCC(=C2c(n3CCc(c24)cccc4)ccc3)CC1 | D5: 0.45 | E5: 0.45 | F5: 3.8e-12 | G5: ADRA1A | H5: HTR2A | I5: 1.3e-35 | J5: 10.379 | K5: Binding | L5: =-LOG10(F5) -> 11.420216 | O5: Ketotifen | P5: CN1CCC(CC1)=C1C2=C(SC=C2)C(=O)CC2=C1C=CC=C2 | Q5: CN1CCC(=C2c(n3CCc(c24)cccc4)ccc3)CC1 | R5: 0.45 | S5: 0.45 | T5: 3.8e-012 | U5: ADRA1A | V5: HTR2A | W5: 1.3e-035 | X5: 15.000 | Y5: Antagonist
A6: Meperidine | B6: CCOC(=O)C1(CCN(C)CC1)C1=CC=CC=C1 | C6: COC(C1(c2ccccc2)CCN(CCCNC(Cc3ccc(C)cc3)=O)CC1)=O | D6: 0.43 | E6: 0.43 | F6: 7.4e-21 | G6: ADRA1A | H6: OPRM1 | I6: 2.7e-21 | J6: 2.56 | K6: Binding | L6: =-LOG10(F6) -> 20.130768 | O6: Meperidine | P6: CCOC(=O)C1(CCN(C)CC1)C1=CC=CC=C1 | Q6: COC(C1(c2ccccc2)CCN(CCCNC(Cc3ccc(C)cc3)=O)CC1)=O | R6: 0.43 | S6: 0.43 | T6: 7.4e-021 | U6: ADRA1A | V6: OPRM1 | W6: 2.7e-021 | X6: 7.800 | Y6: Antagonist
A7: Pizotifen | B7: CN1CCC(CC1)=C3C2C=CSC=2CCc4ccccc34 | C7: CN1CCC(=C2c(n3CCc(c24)cccc4)ccc3)CC1 | D7: 0.52 | E7: 0.52 | F7: 4e-13 | G7: ADRA1A | H7: HTR1B | I7: 1.5e-55 | J7: 0.162 | K7: Binding | L7: =-LOG10(F7) -> 12.39794 | O7: Pizotifen | P7: CN1CCC(CC1)=C3C2C=CSC=2CCc4ccccc34 | Q7: CN1CCC(=C2c(n3CCc(c24)cccc4)ccc3)CC1 | R7: 0.52 | S7: 0.52 | T7: 4.0e-013 | U7: ADRA1A | V7: HTR1B | W7: 1.5e-055 | X7: 1.200 | Y7: Antagonist
A8: Rescinnamine | B8: [H][C@]12C[C@@H](OC(=O)C=CC3=CC(OC)=C(OC)C(OC)=C3)[C@H](OC)[C@@H](C(=O)OC)[C@@]1([H])C[C@@]1([H])N(CCC3=C1NC1=C3C=CC(OC)=C1)C2 | C8: COC([C@@H]1[C@H]([C@H]2CC[C@@H]1O)C[C@H](N3C2)c4c(c(c5[nH]4)cccc5)CC3)=O | D8: 0.48 | E8: 0.79 | F8: 5.8e-10 | G8: ADRA1A | H8: ABCB1 | I8: 150 | J8: 3.5 | K8: Binding | L8: =-LOG10(F8) -> 9.236572
A9: Reserpine | B9: [H][C@]12C[C@@H](OC(=O)C3=CC(OC)=C(OC)C(OC)=C3)[C@H](OC)[C@@H](C(=O)OC)[C@@]1([H])C[C@@]1([H])N(CCC3=C1NC1=C3C=CC(OC)=C1)C2 | C9: COC([C@@H]1[C@H]([C@H]2CC[C@@H]1O)C[C@H](N3C2)c4c(c(c5[nH]4)cccc5)CC3)=O | D9: 0.49 | E9: 0.8 | F9: 2.9e-10 | G9: ADRA1A | H9: SCN10A | I9: 2.7 | J9: 12 | K9: Binding | L9: =-LOG10(F9) -> 9.537602
A10: Tripelennamine | B10: CN(C)CCN(CC1=CC=CC=C1)C1=NC=CC=C1 | C10: Clc1c(N2CCN(Cc3ccccc3)CC2)nccc1 | D10: 0.27 | E10: 0.69 | F10: 2.4e-06 | G10: ADRA1A | H10: HRH1 | I10: 4e-24 | J10: 10.764 | K10: Binding | L10: =-LOG10(F10) -> 5.6197888
A11: Benzquinamide | B11: CCN(CC)C(=O)C1CN2CCC3=C(C=C(OC)C(OC)=C3)C2CC1OC(C)=O | C11: COc1c(OC)cc(c2c1)CN(Cc3c(c4c(OC)cc3)cc(C(N5CCC(N6CCCC6)CC5)=O)o4)CC2 | D11: 0.31 | E11: 0.51 | F11: 8e-40 | G11: ADRA2A | H11: CHRM5 | I11: 4.9e-29 | J11: 0.825 | K11: Binding | L11: =-LOG10(F11) -> 39.09691 | O11: Benzquinamide | P11: CCN(CC)C(=O)C1CN2CCC3=C(C=C(OC)C(OC)=C3)C2CC1OC(C)=O | Q11: COc1c(OC)cc(c2c1)CN(Cc3c(c4c(OC)cc3)cc(C(N5CCC(N6CCCC6)CC5)=O)o4)CC2 | R11: 0.31 | S11: 0.51 | T11: 8.0e-040 | U11: ADRA2A | V11: CHRM5 | W11: 4.9e-029 | X11: 0.450 | Y11: Antagonist
A12: Buphenin | B12: CC(CCc1ccccc1)NC(C)C(O)c2ccc(O)cc2 | C12: C[C@H](N1CCC(Cc2ccccc2)CC1)[C@@H](c3ccc(O)cc3)O | D12: 0.43 | E12: 0.72 | F12: 1.7e-18 | G12: ADRA2A | H12: ADRA1B | I12: 2.7e-40 | J12: 9.39 | K12: Binding | L12: =-LOG10(F12) -> 17.769551
A13: Dextromethorphan | B13: [H][C@]12CCCC[C@]11CCN(C)[C@H]2CC2=C1C=C(OC)C=C2 | C13: COc1cc(c2cc1)C3[C@H](N(C)CCO3)CC2 | D13: 0.4 | E13: 0.71 | F13: 1.7e-22 | G13: ADRA2A | H13: CHRM1 | I13: 3.3e-27 | J13: 11.172 | K13: Binding | L13: =-LOG10(F13) -> 21.769551
A14: Dobutamine | B14: CC(CCC1=CC=C(O)C=C1)NCCC1=CC(O)=C(O)C=C1 | C14: NCCc1cc(O)c(O)cc1 | D14: 0.41 | E14: 0.69 | F14: 3e-26 | G14: ADRA2A | H14: ADRB2 | I14: 2.7e-35 | J14: 10.831 | K14: Binding | L14: =-LOG10(F14) -> 25.522879
A15: Fasudil | B15: O=S(=O)(N1CCCNCC1)C1=CC=CC2=C1C=CN=C2 | C15: Clc1c(N2CCNCC2)ccnc1 | D15: 0.37 | E15: 0.37 | F15: 1.1e-07 | G15: ADRA2A | H15: CCR2 | I15: 1.5e-09 | J15: 3.99 | K15: Binding | L15: =-LOG10(F15) -> 6.9586073
A16: Levorphanol | B16: [H][C@@]12CCCC[C@@]11CCN(C)[C@@H]2CC2=C1C=C(O)C=C2 | C16: CN1[C@H]2C(c(c3CC2)cc(O)cc3)OCC1 | D16: 0.38 | E16: 0.7 | F16: 3.9e-16 | G16: ADRA2A | H16: OPRM1 | I16: 2.7e-19 | J16: 8.98 | K16: Binding | L16: =-LOG10(F16) -> 15.408935 | O16: Levorphanol | P16: [H][C@@]12CCCC[C@@]11CCN(C)[C@@H]2CC2=C1C=C(O)C=C2 | Q16: CN1[C@H]2C(c(c3CC2)cc(O)cc3)OCC1 | R16: 0.38 | S16: 0.70 | T16: 3.9e-016 | U16: ADRA2A | V16: OPRM1 | W16: 2.7e-019 | X16: 8.980 | Y16: Antagonist
A17: Pizotifen | B17: CN1CCC(CC1)=C3C2C=CSC=2CCc4ccccc34 | C17: CN1CCC(=C2c(n3CCc(c24)cccc4)ccc3)CC1 | D17: 0.52 | E17: 0.52 | F17: 2e-09 | G17: ADRA2A | H17: HTR1B | I17: 3.6e-41 | J17: 0.577 | K17: Binding | L17: =-LOG10(F17) -> 8.69897 | O17: Pizotifen | P17: CN1CCC(CC1)=C3C2C=CSC=2CCc4ccccc34 | Q17: CN1CCC(=C2c(n3CCc(c24)cccc4)ccc3)CC1 | R17: 0.52 | S17: 0.52 | T17: 2.0e-009 | U17: ADRA2A | V17: HTR1B | W17: 3.6e-041 | X17: 7.250 | Y17: Antagonist
A18: Buphenin | B18: CC(CCc1ccccc1)NC(C)C(O)c2ccc(O)cc2 | C18: CNCC(c1cc(O)ccc1)O | D18: 0.28 | E18: 0.7 | F18: 1.4e-18 | G18: ADRA2B | H18: ADRA1B | I18: 3.6e-41 | J18: 0.733 | K18: Binding | L18: =-LOG10(F18) -> 17.853872
A19: Dobutamine | B19: CC(CCC1=CC=C(O)C=C1)NCCC1=CC(O)=C(O)C=C1 | C19: NCCc1cc(O)c(O)cc1 | D19: 0.41 | E19: 0.69 | F19: 1.9e-26 | G19: ADRA2B | H19: ADRB2 | I19: 3.2e-29 | J19: 5.8 | K19: Binding | L19: =-LOG10(F19) -> 25.721246
A20: Salmeterol | B20: OCC1=C(O)C=CC(=C1)C(O)CNCCCCCCOCCCCC1=CC=CC=C1 | C20: CNCC(c1cc(O)c(O)cc1)O | D20: 0.34 | E20: 0.59 | F20: 7.1e-05 | G20: ADRA2B | H20: ADRB2 | I20: 3.2e-29 | J20: 13.317 | K20: Binding | L20: =-LOG10(F20) -> 4.1487417
A21: Trazodone | B21: ClC1=CC=CC(=C1)N1CCN(CCCN2N=C3C=CC=CN3C2=O)CC1 | C21: Cc1ccc(C(c(c2C(=O)N3CCCCN4CCN(c5cc(Cl)ccc5)CC4)cccc2)=N3)cc1 | D21: 0.52 | E21: 0.52 | F21: 1.6e-08 | G21: ADRA2B | H21: ADRA2A | I21: 6e-105 | J21: 3.44 | K21: Binding | L21: =-LOG10(F21) -> 7.79588
A22: Benzphetamine | B22: CC(CC1=CC=CC=C1)N(C)CC1=CC=CC=C1 | C22: CN(c1ccccc1)CC(NCC2)=N2 | D22: 0.26 | E22: 0.63 | F22: 6.1e-06 | G22: ADRA2C | H22: ADRA2A | I22: 7.9e-101 | J22: 0.681 | K22: Binding | L22: =-LOG10(F22) -> 5.2146702
A23: Benzquinamide | B23: CCN(CC)C(=O)C1CN2CCC3=C(C=C(OC)C(OC)=C3)C2CC1OC(C)=O | C23: COc1c(OC)cc(c2c1)CN(Cc3c(c4c(OC)cc3)cc(C(N5CCC(N6CCCC6)CC5)=O)o4)CC2 | D23: 0.31 | E23: 0.51 | F23: 8e-40 | G23: ADRA2C | H23: CHRM5 | I23: 5.4e-21 | J23: 1.739 | K23: Binding | L23: =-LOG10(F23) -> 39.09691
A24: Bevantolol | B24: COC1=C(OC)C=C(CCNCC(O)COC2=CC(C)=CC=C2)C=C1 | C24: COc1c(c2ccc1)CCC[C@H]2CNCCc3cc(c4cc3)OCO4 | D24: 0.32 | E24: 0.59 | F24: 3e-09 | G24: ADRA2C | H24: ADRA1B | I24: 1.5e-34 | J24: 9.37 | K24: Binding | L24: =-LOG10(F24) -> 8.5228787
A25: Buphenin | B25: CC(CCc1ccccc1)NC(C)C(O)c2ccc(O)cc2 | C25: CNCC(c1cc(O)ccc1)O | D25: 0.28 | E25: 0.7 | F25: 7.1e-19 | G25: ADRA2C | H25: ADRA1B | I25: 1.5e-34 | J25: 0.641 | K25: Binding | L25: =-LOG10(F25) -> 18.148742
A26: Deserpidine | B26: [H][C@]12C[C@@H](OC(=O)C3=CC(OC)=C(OC)C(OC)=C3)[C@H](OC)[C@@H](C(=O)OC)[C@@]1([H])C[C@@]1([H])N(CCC3=C1NC1=C3C=CC=C1)C2 | C26: COC([C@@H]1[C@H]([C@H]2CC[C@@H]1O)C[C@H](N3C2)c4c(c(c5[nH]4)cccc5)CC3)=O | D26: 0.59 | E26: 0.82 | F26: 1.8e-67 | G26: ADRA2C | H26: SLC18A2 | I26: 8.9 | J26: 11.785 | K26: Binding | L26: =-LOG10(F26) -> 66.744727
A27: Dextromethorphan | B27: [H][C@]12CCCC[C@]11CCN(C)[C@H]2CC2=C1C=C(OC)C=C2 | C27: COc1cc(c2cc1)C3[C@H](N(C)CCO3)CC2 | D27: 0.4 | E27: 0.71 | F27: 1.5e-23 | G27: ADRA2C | H27: CHRM1 | I27: 1.5e-20 | J27: 10.64 | K27: Binding | L27: =-LOG10(F27) -> 22.823909
A28: Dobutamine | B28: CC(CCC1=CC=C(O)C=C1)NCCC1=CC(O)=C(O)C=C1 | C28: NCCc1cc(O)c(O)cc1 | D28: 0.41 | E28: 0.69 | F28: 5.4e-27 | G28: ADRA2C | H28: ADRB2 | I28: 1.6e-24 | J28: 0.49 | K28: Binding | L28: =-LOG10(F28) -> 26.267606
A29: Trazodone | B29: ClC1=CC=CC(=C1)N1CCN(CCCN2N=C3C=CC=CN3C2=O)CC1 | C29: Cc1ccc(C(c(c2C(=O)N3CCCCN4CCN(c5cc(Cl)ccc5)CC4)cccc2)=N3)cc1 | D29: 0.52 | E29: 0.52 | F29: 6.1e-09 | G29: ADRA2C | H29: ADRA2A | I29: 7.9e-101 | J29: 0.353 | K29: Binding | L29: =-LOG10(F29) -> 8.2146702
... A44: Tramadol | B44: COC1=CC=CC(=C1)[C@@]1(O)CCCC[C@@H]1CN(C)C | C44: COc1cc(CN2CCN(CC(C(c3ccccc3)(C4CCC4)O)=O)CC2)ccc1 | D44: 0.3 | E44: 0.65 | F44: 3.8e-08 | G44: CHRM1 | H44: CHRM3 | I44: 1.4e-94 | J44: 11.082 | K44: Binding | L44: =-LOG10(F44) -> 7.4202164
A45: Azatadine | B45: CN1CCC(CC1)=C1C2=NC=CC=C2CCC2=C1C=CC=C2 | C45: CN1CCC(=C2c(n3CCc(c24)cccc4)ccc3)CC1 | D45: 0.5 | E45: 0.5 | F45: 1.2e-09 | G45: CHRM2 | H45: HRH1 | I45: 2.1e-45 | J45: 0.064 | K45: Binding | L45: =-LOG10(F45) -> 8.9208188 | O45: Azatadine | P45: CN1CCC(CC1)=C1C2=NC=CC=C2CCC2=C1C=CC=C2 | Q45: CN1CCC(=C2c(n3CCc(c24)cccc4)ccc3)CC1 | R45: 0.50 | S45: 0.50 | T45: 1.2e-009 | U45: CHRM2 | V45: HRH1 | W45: 2.1e-045 | X45: 0.080 | Y45: Antagonist
A46: Clemastine | B46: CN1CCC[C@@H]1CCO[C@](C)(C1=CC=CC=C1)C1=CC=C(Cl)C=C1 | C46: CN1C(CCC=C2c(c3Cc(c24)cccc4)cccc3)CCCC1 | D46: 0.36 | E46: 0.81 | F46: 2.9e-10 | G46: CHRM2 | H46: HRH1 | I46: 2.1e-45 | J46: 0.929 | K46: Binding | L46: =-LOG10(F46) -> 9.537602 | O46: Clemastine | P46: CN1CCC[C@@H]1CCO[C@](C)(C1=CC=CC=C1)C1=CC=C(Cl)C=C1 | Q46: CN1C(CCC=C2c(c3Cc(c24)cccc4)cccc3)CCCC1 | R46: 0.36 | S46: 0.81 | T46: 2.9e-010 | U46: CHRM2 | V46: HRH1 | W46: 2.1e-045 | X46: 1.420 | Y46: Antagonist
A47: Isopropamide | B47: CC(C)[N+](C)(CCC(C(N)=O)(C1=CC=CC=C1)C1=CC=CC=C1)C(C)C | C47: NC(C(c1ccccc1)(c2ccccc2)CCN3CCCC3)=O | D47: 0.48 | E47: 0.48 | F47: 1.5e-12 | G47: CHRM2 | H47: CHRM4 | I47: 8.1e-143 | J47: 0.007 | K47: Binding | L47: =-LOG10(F47) -> 11.823909 | O47: Isopropamide | P47: CC(C)[N+](C)(CCC(C(N)=O)(C1=CC=CC=C1)C1=CC=CC=C1)C(C)C | Q47: NC(C(c1ccccc1)(c2ccccc2)CCN3CCCC3)=O | R47: 0.48 | S47: 0.48 | T47: 1.5e-012 | U47: CHRM2 | V47: CHRM4 | W47: 8.1e-143 | X47: 0.010 | Y47: Antagonist
A48: Loxapine | B48: CN1CCN(CC1)C1=NC2=C(OC3=C1C=C(Cl)C=C3)C=CC=C2 | C48: CN1CCN(C(c(c2Oc(c34)ccc(Cl)c3)cccc2)=N4)CC1 | D48: 0.82 | E48: 0.82 | F48: 1.4e-10 | G48: CHRM2 | H48: CHRM3 | I48: 6.6e-109 | J48: 1.123 | K48: Binding | L48: =-LOG10(F48) -> 9.853872 | O48: Loxapine | P48: CN1CCN(CC1)C1=NC2=C(OC3=C1C=C(Cl)C=C3)C=CC=C2 | Q48: CN1CCN(C(c(c2Oc(c34)ccc(Cl)c3)cccc2)=N4)CC1 | R48: 0.82 | S48: 0.82 | T48: 1.4e-010 | U48: CHRM2 | V48: CHRM3 | W48: 6.6e-109 | X48: 9.990 | Y48: Antagonist
A49: Ranitidine | B49: CN\C(NCCSCC1=CC=C(CN(C)C)O1)=C/[N+]([O-])=O | C49: CN(Cc1ccc(CSCCNC=C([N+]([O-])=O)NCCSCc2ccc(CN(C)C)o2)o1)C | D49: 0.65 | E49: 0.65 | F49: 2e-50 | G49: CHRM2 | H49: HRH3 | I49: 1.9e-33 | J49: 5.563 | K49: Binding | L49: =-LOG10(F49) -> 49.69897
A50: Dihydroergotamine | B50: [H][C@@]12CCCN1C(=O)[C@H](CC1=CC=CC=C1)N1C(=O)[C@](C)(NC(=O)[C@H]3CN(C)[C@]4([H])CC5=CNC6=C5C(=CC=C6)[C@@]4([H])C3)O[C@@]21O | C50: CCN(S(N[C@@H]1CN(C)[C@H]2[C@@H](c(c(c3[nH]c4)c4C2)ccc3)C1)(=O)=O)CC | D50: 0.4 | E50: 0.4 | F50: 5.8e-10 | G50: DRD1 | H50: HTR6 | I50: 4.2e-47 | J50: 4.81 | K50: Binding | L50: =-LOG10(F50) -> 9.236572 | O50: Dihydroergotamine | P50: [H][C@@]12CCCN1C(=O)[C@H](CC1=CC=CC=C1)N1C(=O)[C@](C)(NC(=O)[C@H]3CN(C)[C@]4([H])CC5=CNC6=C5C(=CC=C6)[C@@]4([H])C3)O[C@@]21O | Q50: CCN(S(N[C@@H]1CN(C)[C@H]2[C@@H](c(c(c3[nH]c4)c4C2)ccc3)C1)(=O)=O)CC | R50: 0.40 | S50: 0.40 | T50: 5.8e-010 | U50: DRD1 | V50: HTR6 | W50: 4.2e-047 | X50: 0.210 | Y50: Agonist
A51: Dobutamine | B51: CC(CCC1=CC=C(O)C=C1)NCCC1=CC(O)=C(O)C=C1 | C51: NCCc1cc(O)c(O)cc1 | D51: 0.41 | E51: 0.67 | F51: 6.8e-60 | G51: DRD1 | H51: ADRB2 | I51: 7.8e-54 | J51: 13 | K51: Agonist | L51: =-LOG10(F51) -> 59.167491
A52: Phenylephrine | B52: CNC[C@H](O)C1=CC(O)=CC=C1 | C52: CCCN(CCc1cc(O)ccc1)CCC | D52: 0.32 | E52: 0.75 | F52: 4.2e-09 | G52: DRD1 | H52: ADRB2 | I52: 7.8e-54 | J52: 2.8 | K52: Agonist | L52: =-LOG10(F52) -> 8.3767507
A53: Terfenadine | B53: CC(C)(C)C1=CC=C(C=C1)C(O)CCCN1CCC(CC1)C(O)(C1=CC=CC=C1)C1=CC=CC=C1 | C53: OC(c1ccc(F)cc1)CCCN2C[C@@H]3[C@@H](N(c4ccccc4)c(c35)cccc5)CC2 | D53: 0.46 | E53: 0.6 | F53: 1.4e-10 | G53: DRD1 | H53: ADRA1A | I53: 2e-45 | J53: 9.087 | K53: Binding | L53: =-LOG10(F53) -> 9.853872
A54: Masoprocol | B54: C[C@@H](CC1=CC(O)=C(O)C=C1)[C@H](C)CC1=CC(O)=C(O)C=C1 | C54: NCCc1cc(O)c(O)cc1 | D54: 0.48 | E54: 0.65 | F54: 7.6e-05 | G54: DRD2 | H54: LTB4R | I54: 9.3e-05 | J54: 6.9 | K54: Binding | L54: =-LOG10(F54) -> 4.1191864
...

Sheet FalsePDB
A1: Target | B1: Drug | C1: Confidence_score | D1: Affinity | E1: Affinity_score | F1: Experiment_result | G1: Affinity uM
A2: ADORA1 | B2: bucladesine | C2: 0.9253071 | D2: 1.0795232 | E2: 0.060454492 | F2: inactive | G2: =POWER(10,D2) -> 12.009452
A3: ADORA1 | B3: Cytarabine | C3: 0.94714385 | D3: 2.5570712 | E3: 0.58842611 | F3: inactive | G3: =POWER(10,D3) -> 360.63777
A4: ADORA1 | B4: Didanosine | C4: 0.95163631 | D4: 2.3588605 | E4: 0.56916845 | F4: inactive | G4: =POWER(10,D4) -> 228.48647
A6: ADORA1 | B6: Famciclovir | C6: 0.93519241 | D6: 1.5340804 | E6: 0.2221307 | F6: inactive | G6: =POWER(10,D6) -> 34.204275
A7: ADORA1 | B7: Gemcitabine | C7: 0.95388395 | D7: 1.627334 | E7: 0.77578574 | F7: inactive | G7: =POWER(10,D7) -> 42.39689
A8: ADORA1 | B8: Pentoxifylline | C8: 0.94605935 | D8: 1.8598459 | E8: 0.91201836 | F8: inactive | G8: =POWER(10,D8) -> 72.417892
A9: ADORA1 | B9: Ribavirin | C9: 0.95010531 | D9: 1.9574767 | E9: 0.53540277 | F9: inactive | G9: =POWER(10,D9) -> 90.672739
A10: ADORA1 | B10: Zalcitabine | C10: 0.94809312 | D10: 1.4043844 | E10: 0.50241858 | F10: inactive | G10: =POWER(10,D10) -> 25.373734
A12: ADORA2A | B12: bucladesine | C12: 0.93446368 | D12: 0.38968557 | E12: 0.10054056 | F12: inactive | G12: =POWER(10,D12) -> 2.4529324
A13: ADORA2A | B13: Cytarabine | C13: 0.94464916 | D13: 2.0427051 | E13: 0.33682376 | F13: inactive | G13: =POWER(10,D13) -> 110.33291
A14: ADORA2A | B14: Didanosine | C14: 0.94976139 | D14: 1.9167298 | E14: 0.22432931 | F14: inactive | G14: =POWER(10,D14) -> 82.55242
A15: ADORA2A | B15: Famciclovir | C15: 0.94129574 | D15: 0.68967658 | E15: 0.16683197 | F15: inactive | G15: =POWER(10,D15) -> 4.8941422
... A540: TBXA2R | B540: tolbutamide | C540: 0.92213821 | D540: 1.9756138 | E540: 0.13213828 | F540: inactive | G540: =POWER(10,D540) -> 94.539616
A542: averages | C542: =AVERAGE(C2:C540) -> 0.87294547
C543: =STDEV(C2:C540) -> 0.082499969

Sheet FalseUni
A1: Target | B1: Drug | C1: Confidence_score | D1: Affinity, boltz2 | E1: Affinity_score | F1: Affinity, uM
A2: ADORA1 | B2: bucladesine | C2: 0.93567669 | D2: 1.0697904 | E2: 0.060584925 | F2: =EXP(D2) -> 2.9147684
A3: ADORA1 | B3: Cytarabine | C3: 0.95273161 | D3: 2.4433193 | E3: 0.55031437 | F3: =EXP(D3) -> 11.511187
A4: ADORA1 | B4: Didanosine | C4: 0.95161057 | D4: 2.196547 | E4: 0.57486355 | F4: =EXP(D4) -> 8.9939042
A5: ADORA1 | B5: Etomidate | C5: 0.94985467 | D5: 0.36573595 | E5: 0.34898129 | F5: =EXP(D5) -> 1.4415745
A6: ADORA1 | B6: Famciclovir | C6: 0.93766165 | D6: 0.89800185 | E6: 0.17877656 | F6: =EXP(D6) -> 2.4546934
A7: ADORA1 | B7: Gemcitabine | C7: 0.95229816 | D7: 1.6720136 | E7: 0.80556256 | F7: =EXP(D7) -> 5.3228754
A8: ADORA1 | B8: Pentoxifylline | C8: 0.94539851 | D8: 1.9626228 | E8: 0.87790233 | F8: =EXP(D8) -> 7.1179713
A9: ADORA1 | B9: Ribavirin | C9: 0.9494282 | D9: 1.7080907 | E9: 0.62844151 | F9: =EXP(D9) -> 5.5184149
A10: ADORA1 | B10: Zalcitabine | C10: 0.94925368 | D10: 1.4252604 | E10: 0.54183823 | F10: =EXP(D10) -> 4.1589408
A11: ADORA2A | B11: Acyclovir | C11: 0.80032778 | D11: 1.9888171 | E11: 0.55087888 | F11: =EXP(D11) -> 7.3068853
A12: ADORA2A | B12: bucladesine | C12: 0.86359656 | D12: 0.10791463 | E12: 0.10809501 | F12: =EXP(D12) -> 1.1139526
A13: ADORA2A | B13: Cytarabine | C13: 0.86797732 | D13: 1.8462634 | E13: 0.49833456 | F13: =EXP(D13) -> 6.3360998
... A540: TBXA2R | B540: tolbutamide | C540: 0.55502892 | D540: 0.91724777 | E540: 0.13431799 | F540: =EXP(D540) -> 2.5023937
A542: averages | C542: =AVERAGE(C2:C540) -> 0.77707061
C543: =STDEV(C2:C540) -> 0.086339042

Sheet FalseSea
A1: o_name | B1: chembl | C1: E-value | D1: Max Tc | E1: Charge Filter | F1: Charge Probability | G1: o_chemblgene | H1: gene_id | I1: Prediction_id | J1: log10
A2: bucladesine | B2: AA1R | C2: 3.3043386e-115 | D2: 0.697446 | E2: Pass | F2: 0.10933148 | G2: AA1R_HUMAN | H2: 134 | I2: 7 | J2: =-LOG10(C2) -> 114.48092
A3: Cytarabine | B3: AA1R | C3: 2.1372398e-53 | D3: 0.663073 | E3: Pass | F3: 0.81615599 | G3: AA1R_HUMAN | H3: 134 | I3: 32 | J3: =-LOG10(C3) -> 52.670147
A4: Didanosine | B4: AA1R | C4: 6.8006523e-86 | D4: 0.706044 | E4: Pass | F4: 0.81615599 | G4: AA1R_HUMAN | H4: 134 | I4: 10 | J4: =-LOG10(C4) -> 85.167449
A5: Etomidate | B5: AA1R | C5: 4.1470503e-08 | D5: 0.358209 | E5: Pass | F5: 0.84815618 | G5: AA1R_BOVIN | H5: 134 | I5: 1903 | J5: =-LOG10(C5) -> 7.3822607
A6: Famciclovir | B6: AA1R | C6: 1.0866139e-07 | D6: 0.632959 | E6: Pass | F6: 0.81615599 | G6: AA1R_HUMAN | H6: 134 | I6: 838 | J6: =-LOG10(C6) -> 6.9639248
A7: Gemcitabine | B7: AA1R | C7: 4.3214292e-18 | D7: 0.576355 | E7: Pass | F7: 0.81615599 | G7: AA1R_HUMAN | H7: 134 | I7: 123 | J7: =-LOG10(C7) -> 17.364373
A8: Pentoxifylline | B8: AA1R | C8: 1.1334844e-86 | D8: 0.873418 | E8: Pass | F8: 0.81615599 | G8: AA1R_HUMAN | H8: 134 | I8: 55 | J8: =-LOG10(C8) -> 85.945584
A9: Ribavirin | B9: AA1R | C9: 1.3188534e-42 | D9: 0.415094 | E9: Pass | F9: 0.81615599 | G9: AA1R_HUMAN | H9: 134 | I9: 62 | J9: =-LOG10(C9) -> 41.879803
A10: Zalcitabine | B10: AA1R | C10: 3.5425178e-20 | D10: 0.598916 | E10: Pass | F10: 0.81615599 | G10: AA1R_HUMAN | H10: 134 | I10: 91 | J10: =-LOG10(C10) -> 19.450688
A11: Acyclovir | B11: AA2AR | C11: 5.5300265e-06 | D11: 0.534965 | E11: Pass | F11: 0.85714286 | G11: AA2AR_CAVPO | H11: 135 | I11: 2152 | J11: =-LOG10(C11) -> 5.2572728
A12: bucladesine | B12: AA2AR | C12: 4.8309473e-62 | D12: 0.693642 | E12: Pass | F12: 0.14225941 | G12: AA2AR_HUMAN | H12: 135 | I12: 230 | J12: =-LOG10(C12) -> 61.315968
A13: Cytarabine | B13: AA2AR | C13: 4.5789298e-36 | D13: 0.655914 | E13: Pass | F13: 0.69246862 | G13: AA2AR_HUMAN | H13: 135 | I13: 58 | J13: =-LOG10(C13) -> 35.339236
... A540: tolbutamide | B540: TA2R | C540: 5.1641663e-13 | D540: 0.600823 | E540: Pass | F540: 0.79104478 | G540: TA2R_HUMAN | H540: 6915 | I540: 1480 | J540: =-LOG10(C540) -> 12.287
D542: =AVERAGE(D2:D540) -> 0.61238107 | I542: average | J542: =AVERAGE(J2:J540) -> 18.759684
D543: =STDEV(D2:D540) -> 0.1334854 | J543: =STDEV(J2:J540) -> 23.206101

Sheet Below_0.8
B1: True PDB | C1: False PDB
A2: ADRA1A
A3: ADRA2A
A4: ADRA2B
A5: ADRA2C
A6: ADRB1
A7: ADRB2
A8: AR
A9: CHRM1
A10: CHRM2
A11: DRD1
A12: DRD2
A13: DRD3
... A35: TACR1

Sheet Confidence Score Cutoff
A1: Cutoff | B1: TP PDB ≥ cutoff | C1: FP PDB ≥ cutoff | D1: Precision PDB | F1: TP Uni ≥ cutoff | G1: FP Uni ≥ cutoff | H1: Precision Uni
A2: 0.6 | B2: =COUNTIF(TruePDB!C:C, ">=" & A2) -> 120 | C2: =COUNTIF(FalsePDB!C:C, ">=" & A2) -> 276 | D2: =IF(B2 + C2 = 0, "", B2 / (B2 + C2)) -> 0.3030303 | F2: =COUNTIF(TrueUni!C:C, ">=" & A2) -> 109 | G2: =COUNTIF(FalseUni!C:C, ">=" & A2) -> 512 | H2: =IF(F2 + G2 = 0, "", F2 / (F2 + G2)) -> 0.17552335
A3: 0.7 | B3: =COUNTIF(TruePDB!C:C, ">=" & A3) -> 116 | C3: =COUNTIF(FalsePDB!C:C, ">=" & A3) -> 266 | D3: =IF(B3 + C3 = 0, "", B3 / (B3 + C3)) -> 0.30366492 | F3: =COUNTIF(TrueUni!C:C, ">=" & A3) -> 105 | G3: =COUNTIF(FalseUni!C:C, ">=" & A3) -> 461 | H3: =IF(F3 + G3 = 0, "", F3 / (F3 + G3)) -> 0.18551237
A4: 0.8 | B4: =COUNTIF(TruePDB!C:C, ">=" & A4) -> 107 | C4: =COUNTIF(FalsePDB!C:C, ">=" & A4) -> 219 | D4: =IF(B4 + C4 = 0, "", B4 / (B4 + C4)) -> 0.32822086 | F4: =COUNTIF(TrueUni!C:C, ">=" & A4) -> 39 | G4: =COUNTIF(FalseUni!C:C, ">=" & A4) -> 213 | H4: =IF(F4 + G4 = 0, "", F4 / (F4 + G4)) -> 0.1547619
A5: 0.9 | B5: =COUNTIF(TruePDB!C:C, ">=" & A5) -> 67 | C5: =COUNTIF(FalsePDB!C:C, ">=" & A5) -> 144 | D5: =IF(B5 + C5 = 0, "", B5 / (B5 + C5)) -> 0.31753555 | F5: =COUNTIF(TrueUni!C:C, ">=" & A5) -> 3 | G5: =COUNTIF(FalseUni!C:C, ">=" & A5) -> 20 | H5: =IF(F5 + G5 = 0, "", F5 / (F5 + G5)) -> 0.13043478

Sheet cutoff results
A1: Cutoff | B1: Precision PDB | C1: Precision Uni
A2: 0.6 | B2: 0.3030303 | C2: 0.17552335
A3: 0.7 | B3: 0.30366492 | C3: 0.18551237
A4: 0.8 | B4: 0.32822086 | C4: 0.1547619
A5: 0.9 | B5: 0.31753555 | C5: 0.13043478

Sheet True_affinity
A1: Target | B1: Drug | C1: PDB affinity | D1: uniprot affinity | E1: Confirmed activity | H1: Confirmed activity | I1: uniprot affinity
A2: ADRA1A | B2: Azatadine | C2: 0.02389339 | D2: 0.47010649 | E2: 8.642 | H2: 8.642 | I2: 0.47010649
A3: ADRA1A | B3: Domperidone | C3: 0.026922335 | D3: 0.26587713 | E3: 0.128 | H3: 0.128 | I3: 0.26587713
A4: ADRA1A | B4: Dyclonine | C4: 0.76874587 | D4: 1.0799689 | E4: 9.658 | H4: 9.658 | I4: 1.0799689
A5: ADRA1A | B5: Ketotifen | C5: 0.027409186 | D5: 0.18062899 | E5: 10.379 | H5: 10.379 | I5: 0.18062899
A6: ADRA1A | B6: Meperidine | C6: 0.32131536 | D6: 0.77478222 | E6: 2.56 | H6: 2.56 | I6: 0.77478222
A7: ADRA1A | B7: Pizotifen | C7: 0.011796694 | D7: 0.1955008 | E7: 0.162 | H7: 0.162 | I7: 0.1955008
A8: ADRA1A | B8: Rescinnamine | C8: 6.1333818 | D8: 1.3467883 | E8: 3.5 | H8: 3.5 | I8: 1.3467883
A9: ADRA1A | B9: Reserpine | C9: 0.11589239 | D9: 0.26025061 | E9: 12 | H9: 12 | I9: 0.26025061
A10: ADRA1A | B10: Tripelennamine | C10: 1.1642901 | D10: 1.0058727 | E10: 10.764 | H10: 10.764 | I10: 1.0058727
A11: ADRA2A | B11: Benzquinamide | C11: 0.053205299 | D11: 0.41726172 | E11: 0.825 | H11: 0.825 | I11: 0.41726172
A12: ADRA2A | B12: Buphenin | C12: 0.80681266 | D12: 0.66294792 | E12: 9.39 | H12: 9.39 | I12: 0.66294792
A13: ADRA2A | B13: Dextromethorphan | C13: 5.2789628 | D13: 0.24711224 | E13: 11.172 | H13: 11.172 | I13: 0.24711224
... A21: ADRA2B | B21: Trazodone | C21: 0.1647536 | D21: 0.69085826 | E21: 3.44 | H21: 3.44 | I21: 0.69085826
A22: ADRA2C | B22: Benzphetamine | D22: 0.45521456 | E22: 0.681 | H22: 0.681 | I22: 0.45521456
A23: ADRA2C | B23: Benzquinamide | D23: 0.77028397 | E23: 1.739 | H23: 1.739 | I23: 0.77028397
A24: ADRA2C | B24: Bevantolol | D24: 1.1345228 | E24: 9.37 | H24: 9.37 | I24: 1.1345228
A25: ADRA2C | B25: Buphenin | D25: 0.60383114 | E25: 0.641 | H25: 0.641 | I25: 0.60383114
A26: ADRA2C | B26: Deserpidine | D26: 1.1779254 | E26: 11.785 | H26: 11.785 | I26: 1.1779254
A27: ADRA2C | B27: Dextromethorphan | D27: 0.35388566 | E27: 10.64 | H27: 10.64 | I27: 0.35388566
A28: ADRA2C | B28: Dobutamine | D28: 0.25719879 | E28: 0.49 | H28: 0.49 | I28: 0.25719879
A29: ADRA2C | B29: Trazodone | D29: 0.45992914 | E29: 0.353 | H29: 0.353 | I29: 0.45992914
A30: ADRA2C | B30: Verapamil | D30: 1.9566196 | E30: 4.331 | H30: 4.331 | I30: 1.9566196
A31: ADRB1 | B31: Tamsulosin | C31: 0.0037316741 | D31: 0.22082994 | E31: 2.5 | H31: 2.5 | I31: 0.22082994
A32: ADRB2 | B32: Desloratadine | C32: 0.72197119 | D32: 0.61769623 | E32: 12.546 | H32: 12.546 | I32: 0.61769623
A33: ADRB2 | B33: Pimozide | C33: 0.019815882 | D33: 0.19759083 | E33: 6.3 | H33: 6.3 | I33: 0.19759083
A34: ADRB2 | B34: Pizotifen | C34: 0.080881788 | D34: 0.39024781 | E34: 5.8 | H34: 5.8 | I34: 0.39024781
A35: ADRB2 | B35: Prenylamine | C35: 0.18161666 | D35: 0.42938031 | E35: 3.486 | H35: 3.486 | I35: 0.42938031
A36: ADRB2 | B36: Tamsulosin | C36: 0.0094757536 | D36: 0.18781872 | E36: 2.2 | H36: 2.2 | I36: 0.18781872
A37: AR | B37: Dihydrotachysterol | C37: 0.49501614 | D37: 0.29941317 | E37: 17 | H37: 17 | I37: 0.29941317
A38: AR | B38: Fluorometholone | C38: 0.015241769 | D38: 0.10975098 | E38: 0.829 | H38: 0.829 | I38: 0.10975098
A39: AR | B39: Medrysone | C39: 0.067737757 | D39: 0.24463133 | E39: 0.257 | H39: 0.257 | I39: 0.24463133
A40: AR | B40: Prednicarbate | C40: 0.070911837 | D40: 0.87892356 | E40: 0.71 | H40: 0.71 | I40: 0.87892356
A41: CHRM1 | B41: Azatadine | C41: 0.38442545 | D41: 0.60718508 | E41: 0.111 | H41: 0.111 | I41: 0.60718508
A42: CHRM1 | B42: Clemastine | C42: 0.010468632 | D42: 0.16726659 | E42: 0.135 | H42: 0.135 | I42: 0.16726659
... A129: TACR1 | B129: Haloperidol | C129: 0.62096384 | D129: 0.42501553 | E129: 8.162 | H129: 8.162 | I129: 0.42501553

Sheet UnivsConf
A1: Target | B1: Drug | C1: Confirmed activity (uM) | D1: Uniprot affinity (uM) | E1: PDB affinity | G1: log confirmed | H1: log uniprot | I1: log pdb | L1: confirmedvuni | M1: confirmedvpdb | O1: average difference uniprot | P1: average difference PDB | Q1: SD uniprot
A2: ADRA1A | B2: Azatadine | C2: 8.642 | D2: 0.47010649 | E2: 0.02389339 | G2: =LOG10(C2) -> 0.93661426 | H2: =LOG10(D2) -> -0.32780375 | I2: =LOG10(E2) -> -1.6217222 | K2: ADRA1A | L2: =ABS(G2-H2) -> 1.264418 | M2: =ABS(G2-I2) -> 2.5583365 | N2: ADRA1A | O2: =AVERAGE(L2:L10) -> 0.88904619 | P2: =AVERAGE(M2:M10) -> 1.3529479 | Q2: =STDEV(L2:L10) -> 0.5981888
A3: ADRA1A | B3: Domperidone | C3: 0.128 | D3: 0.26587713 | E3: 0.026922335 | G3: =LOG10(C3) -> -0.89279003 | H3: =LOG10(D3) -> -0.57531901 | I3: =LOG10(E3) -> -1.5698873 | K3: ADRA1A | L3: =ABS(G3-H3) -> 0.31747102 | M3: =ABS(G3-I3) -> 0.67709725 | N3: ADRA2A | O3: =AVERAGE(L11:L17) -> 1.0322993 | P3: =AVERAGE(M11:M17) -> 0.73942721 | Q3: =STDEV(L3:L11) -> 0.60921986
A4: ADRA1A | B4: Dyclonine | C4: 9.658 | D4: 1.0799689 | E4: 0.76874587 | G4: =LOG10(C4) -> 0.9848872 | H4: =LOG10(D4) -> 0.033411243 | I4: =LOG10(E4) -> -0.11421721 | K4: ADRA1A | L4: =ABS(G4-H4) -> 0.95147596 | M4: =ABS(G4-I4) -> 1.0991044 | N4: ADRA2B | O4: =AVERAGE(L18:L21) -> 0.618785 | P4: =AVERAGE(M18:M21) -> 0.93567137 | Q4: =STDEV(L4:L12) -> 0.59302077
A5: ADRA1A | B5: Ketotifen | C5: 10.379 | D5: 0.18062899 | E5: 0.027409186 | G5: =LOG10(C5) -> 1.0161555 | H5: =LOG10(D5) -> -0.74321255 | I5: =LOG10(E5) -> -1.5621039 | K5: ADRA1A | L5: =ABS(G5-H5) -> 1.7593681 | M5: =ABS(G5-I5) -> 2.5782594 | N5: ADRA2C | O5: =AVERAGE(L22:L30) -> 0.5210738 | Q5: =STDEV(L5:L13) -> 0.64832165
A6: ADRA1A | B6: Meperidine | C6: 2.56 | D6: 0.77478222 | E6: 0.32131536 | G6: =LOG10(C6) -> 0.40823997 | H6: =LOG10(D6) -> -0.11082035 | I6: =LOG10(E6) -> -0.49306852 | K6: ADRA1A | L6: =ABS(G6-H6) -> 0.51906032 | M6: =ABS(G6-I6) -> 0.90130848 | N6: ADRB1 | O6: =AVERAGE(L31) -> 1.0538821 | P6: =AVERAGE(M31) -> 2.8260363 | Q6: =STDEV(L6:L14) -> 0.63903911
A7: ADRA1A | B7: Pizotifen | C7: 0.162 | D7: 0.1955008 | E7: 0.011796694 | G7: =LOG10(C7) -> -0.79048499 | H7: =LOG10(D7) -> -0.70885147 | I7: =LOG10(E7) -> -1.9282397 | K7: ADRA1A | L7: =ABS(G7-H7) -> 0.081633517 | M7: =ABS(G7-I7) -> 1.1377547 | N7: ADRB2 | O7: =AVERAGE(L32:L36) -> 1.1923121 | P7: =AVERAGE(M32:M36) -> 1.8493741 | Q7: =STDEV(L7:L15) -> 0.64158689
A8: ADRA1A | B8: Rescinnamine | C8: 3.5 | D8: 1.3467883 | E8: 6.1333818 | G8: =LOG10(C8) -> 0.54406804 | H8: =LOG10(D8) -> 0.12929935 | I8: =LOG10(E8) -> 0.7877 | K8: ADRA1A | L8: =ABS(G8-H8) -> 0.41476869 | M8: =ABS(G8-I8) -> 0.24363195 | N8: AR | O8: =AVERAGE(L37:L40) -> 0.68660949 | P8: =AVERAGE(M37:M40) -> 1.2127477 | Q8: =STDEV(L8:L16) -> 0.57490989
A9: ADRA1A | B9: Reserpine | C9: 12 | D9: 0.26025061 | E9: 0.11589239 | G9: =LOG10(C9) -> 1.0791812 | H9: =LOG10(D9) -> -0.58460824 | I9: =LOG10(E9) -> -0.93594509 | K9: ADRA1A | L9: =ABS(G9-H9) -> 1.6637895 | M9: =ABS(G9-I9) -> 2.0151263 | N9: CHRM1 | O9: =AVERAGE(L41:L44) -> 0.73193461 | P9: =AVERAGE(M41:M44) -> 1.0445006 | Q9: =STDEV(L9:L17) -> 0.57247664
A10: ADRA1A | B10: Tripelennamine | C10: 10.764 | D10: 1.0058727 | E10: 1.1642901 | G10: =LOG10(C10) -> 1.0319737 | H10: =LOG10(D10) -> 0.0025430343 | I10: =LOG10(E10) -> 0.066061191 | K10: ADRA1A | L10: =ABS(G10-H10) -> 1.0294307 | M10: =ABS(G10-I10) -> 0.9659125 | N10: CHRM2 | O10: =AVERAGE(L45:L49) -> 0.79686949 | P10: =AVERAGE(M45:M49) -> 1.1308736 | Q10: =STDEV(L10:L18) -> 0.63032176
A11: ADRA2A | B11: Benzquinamide | C11: 0.825 | D11: 0.41726172 | E11: 0.053205299 | G11: =LOG10(C11) -> -0.083546051 | H11: =LOG10(D11) -> -0.37959145 | I11: =LOG10(E11) -> -1.2740451 | K11: ADRA2A | L11: =ABS(G11-H11) -> 0.2960454 | M11: =ABS(G11-I11) -> 1.1904991 | N11: DRD1 | O11: =AVERAGE(L50:L53) -> 0.96776884 | P11: =AVERAGE(M50:M53) -> 1.240531 | Q11: =STDEV(L11:L19) -> 0.63118429
A12: ADRA2A | B12: Buphenin | C12: 9.39 | D12: 0.66294792 | E12: 0.80681266 | G12: =LOG10(C12) -> 0.97266559 | H12: =LOG10(D12) -> -0.17852059 | I12: =LOG10(E12) -> -0.093227297 | K12: ADRA2A | L12: =ABS(G12-H12) -> 1.1511862 | M12: =ABS(G12-I12) -> 1.0658929 | N12: DRD2 | O12: =AVERAGE(L54) -> 1.2480487 | P12: =AVERAGE(M54) -> 1.6336817 | Q12: =STDEV(L12:L20) -> 0.59108064
A13: ADRA2A | B13: Dextromethorphan | C13: 11.172 | D13: 0.24711224 | E13: 5.2789628 | G13: =LOG10(C13) -> 1.0481309 | H13: =LOG10(D13) -> -0.60710574 | I13: =LOG10(E13) -> 0.7225486 | K13: ADRA2A | L13: =ABS(G13-H13) -> 1.6552367 | M13: =ABS(G13-I13) -> 0.32558232 | N13: DRD3 | O13: =AVERAGE(L55:L61) -> 0.67071428 | P13: =AVERAGE(M55:M61) -> 1.074442 | Q13: =STDEV(L13:L21) -> 0.59282139
A14: ADRA2A | B14: Dobutamine | C14: 10.831 | D14: 0.21706735 | E14: 0.43594938 | G14: =LOG10(C14) -> 1.0346686 | H14: =LOG10(D14) -> -0.66340549 | I14: =LOG10(E14) -> -0.36056393 | K14: ADRA2A | L14: =ABS(G14-H14) -> 1.698074 | M14: =ABS(G14-I14) -> 1.3952325 | N14: DRD4 | O14: =AVERAGE(L62:L65) -> 0.66305919 | P14: =AVERAGE(M62:M65) -> 0.91650539 | Q14: =STDEV(L14:L22) -> 0.56723259
A15: ADRA2A | B15: Fasudil | C15: 3.99 | D15: 1.2930066 | E15: 4.8965535 | G15: =LOG10(C15) -> 0.6009729 | H15: =LOG10(D15) -> 0.11160073 | I15: =LOG10(E15) -> 0.6898905 | K15: ADRA2A | L15: =ABS(G15-H15) -> 0.48937217 | M15: =ABS(G15-I15) -> 0.088917608 | N15: GABRA1 | O15: =AVERAGE(L66) -> 1.028419 | P15: =AVERAGE(M66) -> 0.79003806 | Q15: =STDEV(L15:L23) -> 0.45256511
A16: ADRA2A | B16: Levorphanol | C16: 8.98 | D16: 0.28075651 | E16: 1.5073116 | G16: =LOG10(C16) -> 0.95327634 | H16: =LOG10(D16) -> -0.55167016 | I16: =LOG10(E16) -> 0.17820303 | K16: ADRA2A | L16: =ABS(G16-H16) -> 1.5049465 | M16: =ABS(G16-I16) -> 0.77507331 | N16: HRH1 | O16: =AVERAGE(L67:L69) -> 1.3789757 | P16: =AVERAGE(M67:M69) -> 1.8774161 | Q16: =STDEV(L16:L24) -> 0.46146947
A17: ADRA2A | B17: Pizotifen | C17: 0.577 | D17: 0.21376739 | E17: 1.2472933 | G17: =LOG10(C17) -> -0.23882419 | H17: =LOG10(D17) -> -0.67005855 | I17: =LOG10(E17) -> 0.095968589 | K17: ADRA2A | L17: =ABS(G17-H17) -> 0.43123436 | M17: =ABS(G17-I17) -> 0.33479278 | N17: HRH2 | O17: =AVERAGE(L70:L71) -> 0.30597315 | P17: =AVERAGE(M70:M71) -> 0.55996839 | Q17: =STDEV(L17:L25) -> 0.37438955
A18: ADRA2B | B18: Benzphetamine | C18: 0.733 | D18: 0.70111944 | E18: 0.31134214 | G18: =LOG10(C18) -> -0.13489603 | H18: =LOG10(D18) -> -0.15420799 | I18: =LOG10(E18) -> -0.50676209 | K18: ADRA2B | L18: =ABS(G18-H18) -> 0.019311969 | M18: =ABS(G18-I18) -> 0.37186606 | N18: HRH3 | O18: =AVERAGE(L72:L74) -> 1.2308535 | P18: =AVERAGE(M72:M74) -> 2.2154703 | Q18: =STDEV(L18:L26) -> 0.41022872
A19: ADRA2B | B19: Benzquinamide | C19: 5.8 | D19: 1.0380237 | E19: 0.52989503 | G19: =LOG10(C19) -> 0.76342799 | H19: =LOG10(D19) -> 0.016207257 | I19: =LOG10(E19) -> -0.27581015 | K19: ADRA2B | L19: =ABS(G19-H19) -> 0.74722074 | M19: =ABS(G19-I19) -> 1.0392381 | N19: HTR1A | O19: =AVERAGE(L75:L77) -> 0.69660513 | P19: =AVERAGE(M75:M77) -> 1.4571663 | Q19: =STDEV(L19:L27) -> 0.45970015
A20: ADRA2B | B20: Buphenin | C20: 13.317 | D20: 1.2970855 | E20: 1.2958319 | G20: =LOG10(C20) -> 1.1244064 | H20: =LOG10(D20) -> 0.11296859 | I20: =LOG10(E20) -> 0.11254868 | K20: ADRA2B | L20: =ABS(G20-H20) -> 1.0114378 | M20: =ABS(G20-I20) -> 1.0118577 | N20: HTR2A | O20: =AVERAGE(L78:L79) -> 0.73157118 | P20: =AVERAGE(M78:M79) -> 2.7310338 | Q20: =STDEV(L20:L28) -> 0.48108276
A21: ADRA2B | B21: Trazodone | C21: 3.44 | D21: 0.69085826 | E21: 0.1647536 | G21: =LOG10(C21) -> 0.53655844 | H21: =LOG10(D21) -> -0.16061104 | I21: =LOG10(E21) -> -0.7831651 | K21: ADRA2B | L21: =ABS(G21-H21) -> 0.69716949 | M21: =ABS(G21-I21) -> 1.3197235 | N21: HTR2B | O21: =AVERAGE(L80:L85) -> 0.9739007 | P21: =AVERAGE(M80:M85) -> 1.0890103 | Q21: =STDEV(L21:L29) -> 0.49186929
A22: ADRA2C | B22: Benzphetamine | C22: 0.681 | D22: 0.45521456 | G22: =LOG10(C22) -> -0.16685289 | H22: =LOG10(D22) -> -0.34178386 | K22: ADRA2C | L22: =ABS(G22-H22) -> 0.17493097 | N22: HTR2C | O22: =AVERAGE(L86:L88) -> 0.92232314 | P22: =AVERAGE(M86:M88) -> 1.539572 | Q22: =STDEV(L22:L30) -> 0.49361177
A23: ADRA2C | B23: Benzquinamide | C23: 1.739 | D23: 0.77028397 | G23: =LOG10(C23) -> 0.24029958 | H23: =LOG10(D23) -> -0.11334914 | K23: ADRA2C | L23: =ABS(G23-H23) -> 0.35364872 | N23: HTR3A | O23: =AVERAGE(L89) -> 0.63453675 | P23: =AVERAGE(M89) -> 0.17290916 | Q23: =STDEV(L23:L31) -> 0.50341968
A24: ADRA2C | B24: Bevantolol | C24: 9.37 | D24: 1.1345228 | G24: =LOG10(C24) -> 0.97173959 | H24: =LOG10(D24) -> 0.05481324 | K24: ADRA2C | L24: =ABS(G24-H24) -> 0.91692635 | N24: KCNH2 | O24: 0.54512111 | P24: 0.71066008 | Q24: =STDEV(L24:L32) -> 0.53976308
A25: ADRA2C | B25: Buphenin | C25: 0.641 | D25: 0.60383114 | G25: =LOG10(C25) -> -0.19314197 | H25: =LOG10(D25) -> -0.2190845 | K25: ADRA2C | L25: =ABS(G25-H25) -> 0.025942525 | N25: NR3C1 | O25: =AVERAGE(L91:L97) -> 0.83862169 | P25: =AVERAGE(M91:M97) -> 1.2391179 | Q25: =STDEV(L25:L33) -> 0.59813832
A26: ADRA2C | B26: Deserpidine | C26: 11.785 | D26: 1.1779254 | G26: =LOG10(C26) -> 1.0713296 | H26: =LOG10(D26) -> 0.071117796 | K26: ADRA2C | L26: =ABS(G26-H26) -> 1.0002118 | N26: OPRD1 | O26: =AVERAGE(L98) -> 0.81638177 | P26: =AVERAGE(M98) -> 0.78116465 | Q26: =STDEV(L26:L34) -> 0.53368632
A27: ADRA2C | B27: Dextromethorphan | C27: 10.64 | D27: 0.35388566 | G27: =LOG10(C27) -> 1.0269416 | H27: =LOG10(D27) -> -0.45113703 | K27: ADRA2C | L27: =ABS(G27-H27) -> 1.4780787 | N27: OPRK1 | O27: =AVERAGE(L99:L105) -> 0.77827577 | P27: =AVERAGE(M99:M105) -> 0.97584516 | Q27: =STDEV(L27:L35) -> 0.53278004
A28: ADRA2C | B28: Dobutamine | C28: 0.49 | D28: 0.25719879 | G28: =LOG10(C28) -> -0.30980392 | H28: =LOG10(D28) -> -0.58973108 | K28: ADRA2C | L28: =ABS(G28-H28) -> 0.27992716 | N28: OPRM1 | O28: =AVERAGE(L106:L107) -> 0.55858754 | P28: =AVERAGE(M106:M107) -> 0.66593246 | Q28: =STDEV(L28:L36) -> 0.49401228
A29: ADRA2C | B29: Trazodone | C29: 0.353 | D29: 0.45992914 | G29: =LOG10(C29) -> -0.45222529 | H29: =LOG10(D29) -> -0.33730908 | K29: ADRA2C | L29: =ABS(G29-H29) -> 0.11491622 | N29: PDE4D | O29: =AVERAGE(L108:L109) -> 1.066155 | P29: =AVERAGE(M108:M109) -> 1.5347988 | Q29: =STDEV(L29:L37) -> 0.5206882
A30: ADRA2C | B30: Verapamil | C30: 4.331 | D30: 1.9566196 | G30: =LOG10(C30) -> 0.63658818 | H30: =LOG10(D30) -> 0.29150639 | K30: ADRA2C | L30: =ABS(G30-H30) -> 0.34508179 | N30: PGR | O30: =AVERAGE(L110:L118) -> 1.2470512 | P30: =AVERAGE(M110:M118) -> 1.396553 | Q30: =STDEV(L30:L38) -> 0.40260641
A31: ADRB1 | B31: Tamsulosin | C31: 2.5 | D31: 0.22082994 | E31: 0.0037316741 | G31: =LOG10(C31) -> 0.39794001 | H31: =LOG10(D31) -> -0.65594205 | I31: =LOG10(E31) -> -2.4280963 | K31: ADRB1 | L31: =ABS(G31-H31) -> 1.0538821 | M31: =ABS(G31-I31) -> 2.8260363 | N31: PTGS1 | O31: =AVERAGE(L119:L120) -> 1.4017559 | P31: =AVERAGE(M119:M120) -> 1.5410877 | Q31: =STDEV(L31:L39) -> 0.48543858
A32: ADRB2 | B32: Desloratadine | C32: 12.546 | D32: 0.61769623 | E32: 0.72197119 | G32: =LOG10(C32) -> 1.0985053 | H32: =LOG10(D32) -> -0.20922505 | I32: =LOG10(E32) -> -0.14148013 | K32: ADRB2 | L32: =ABS(G32-H32) -> 1.3077303 | M32: =ABS(G32-I32) -> 1.2399854 | N32: SLC6A2 | O32: =AVERAGE(L121) -> 0.97847165 | P32: =AVERAGE(M121) -> 1.1223759 | Q32: =STDEV(L32:L40) -> 0.58585314
A33: ADRB2 | B33: Pimozide | C33: 6.3 | D33: 0.19759083 | E33: 0.019815882 | G33: =LOG10(C33) -> 0.79934055 | H33: =LOG10(D33) -> -0.7042332 | I33: =LOG10(E33) -> -1.7029866 | K33: ADRB2 | L33: =ABS(G33-H33) -> 1.5035738 | M33: =ABS(G33-I33) -> 2.5023271 | N33: SLC6A3 | O33: =AVERAGE(L122:L125) -> 0.77467439 | P33: =AVERAGE(M122:M125) -> 0.84888974 | Q33: =STDEV(L33:L41) -> 0.57518504
A34: ADRB2 | B34: Pizotifen | C34: 5.8 | D34: 0.39024781 | E34: 0.080881788 | G34: =LOG10(C34) -> 0.76342799 | H34: =LOG10(D34) -> -0.40865953 | I34: =LOG10(E34) -> -1.0921493 | K34: ADRB2 | L34: =ABS(G34-H34) -> 1.1720875 | M34: =ABS(G34-I34) -> 1.8555773 | N34: SLC6A4 | O34: =AVERAGE(L126:L128) -> 0.81181434 | P34: =AVERAGE(M126:M128) -> 0.99173613 | Q34: =STDEV(L34:L42) -> 0.58357378
A35: ADRB2 | B35: Prenylamine | C35: 3.486 | D35: 0.42938031 | E35: 0.18161666 | G35: =LOG10(C35) -> 0.54232738 | H35: =LOG10(D35) -> -0.36715788 | I35: =LOG10(E35) -> -0.74084431 | K35: ADRB2 | L35: =ABS(G35-H35) -> 0.90948526 | M35: =ABS(G35-I35) -> 1.2831717 | N35: TACR1 | O35: 1.2833918 | P35: 1.1187303 | Q35: =STDEV(L35:L43) -> 0.56989761
A36: ADRB2 | B36: Tamsulosin | C36: 2.2 | D36: 0.18781872 | E36: 0.0094757536 | G36: =LOG10(C36) -> 0.34242268 | H36: =LOG10(D36) -> -0.72626113 | I36: =LOG10(E36) -> -2.0233862 | K36: ADRB2 | L36: =ABS(G36-H36) -> 1.0686838 | M36: =ABS(G36-I36) -> 2.3658089
A37: AR | B37: Dihydrotachysterol | C37: 17 | D37: 0.29941317 | E37: 0.49501614 | G37: =LOG10(C37) -> 1.2304489 | H37: =LOG10(D37) -> -0.5237291 | I37: =LOG10(E37) -> -0.30538064 | K37: AR | L37: =ABS(G37-H37) -> 1.754178 | M37: =ABS(G37-I37) -> 1.5358296
A38: AR | B38: Fluorometholone | C38: 0.829 | D38: 0.10975098 | E38: 0.015241769 | G38: =LOG10(C38) -> -0.081445469 | H38: =LOG10(D38) -> -0.9595916 | I38: =LOG10(E38) -> -1.8169646 | K38: AR | L38: =ABS(G38-H38) -> 0.87814613 | M38: =ABS(G38-I38) -> 1.7355192
A39: AR | B39: Medrysone | C39: 0.257 | D39: 0.24463133 | E39: 0.067737757 | G39: =LOG10(C39) -> -0.59006688 | H39: =LOG10(D39) -> -0.61148792 | I39: =LOG10(E39) -> -1.1691692 | K39: AR | L39: =ABS(G39-H39) -> 0.021421045 | M39: =ABS(G39-I39) -> 0.57910231
A40: AR | B40: Prednicarbate | C40: 0.71 | D40: 0.87892356 | E40: 0.070911837 | G40: =LOG10(C40) -> -0.14874165 | H40: =LOG10(D40) -> -0.056048894 | I40: =LOG10(E40) -> -1.1492813 | K40: AR | L40: =ABS(G40-H40) -> 0.092692757 | M40: =ABS(G40-I40) -> 1.0005396
...

Sheet average differences
B1: average difference uniprot | C1: average difference PDB
A2: ADRA1A | B2: 0.88904619 | C2: 1.3529479
A3: ADRA2A | B3: 1.0322993 | C3: 0.73942721
A4: ADRA2B | B4: 0.618785 | C4: 0.93567137
A5: ADRA2C | B5: 0.5210738
A6: ADRB1 | B6: 1.0538821 | C6: 2.8260363
A7: ADRB2 | B7: 1.1923121 | C7: 1.8493741
A8: AR | B8: 0.68660949 | C8: 1.2127477
A9: CHRM1 | B9: 0.73193461 | C9: 1.0445006
A10: CHRM2 | B10: 0.79686949 | C10: 1.1308736
A11: DRD1 | B11: 0.96776884 | C11: 1.240531
A12: DRD2 | B12: 1.2480487 | C12: 1.6336817
A13: DRD3 | B13: 0.67071428 | C13: 1.074442
A14: DRD4 | B14: 0.66305919 | C14: 0.91650539
A15: GABRA1 | B15: 1.028419 | C15: 0.79003806
A16: HRH1 | B16: 1.3789757 | C16: 1.8774161
A17: HRH2 | B17: 0.30597315 | C17: 0.55996839
... A35: TACR1 | B35: 1.2833918 | C35: 1.1187303
B36: =AVERAGE(B2:B35) -> 0.88458422 | C36: =AVERAGE(C2:C35) -> 1.2520065
